Workbook

Sheet README
A1: NETGEAR BoM Catalog — Read Me
A2: Built from 5 datasheets (M4250, M4350, PR460X, WBE718, WBE758). Font: Outfit (install from fonts.google.com/specimen/Outfit if it doesn't render).
A4: Purpose | B4: Single source of product data for the Network BOM Builder: the tool reads these tables to pick switches, PSUs, optics and support SKUs from IDF/MDF, endpoint and redundancy inputs.
A6: Sheet | B6: What it holds
A7: Products | B7: One row per base model. Physical, ports, PoE, power, performance, AV features, environment, commercial. Key = Product_ID.
A8: SKUs | B8: Every orderable variant (region, TAA). Many-to-one with Products.
A9: Accessories | B9: PSUs, adapters, optics, DACs/AOCs, trays, licenses, support packs. Key = Orderable_SKU, grouped by Base_Model.
A10: Compatibility | B10: Which accessories fit which product or family, with slot/port type and max qty.
A11: PSU_PoE_Matrix | B11: Exact PoE budget for every PSU combination (EPS total + protected/RPS). Use this rather than a single 'max' number.
A12: Design_Rules | B12: Footnote-level constraints the engine must enforce (25G block speed, stacking vs AVB/PTP, PoE classes, Insight vs Engage...).
A13: Model_Lookup | B13: Example of formula-driven lookups against the tables.
A14: Data_Dictionary | B14: Every column with unit/type, plus recommended future fields.
A15: Data_Gaps | B15: Datasheet conflicts and missing data, with the assumption loaded.
A16: Endpoints | B16: Endpoint library the BoM tool loads: link speed, media, PoE allocation, stream Mbps.
... A19: Lists | B19: Dropdown values used for data validation.
A21: How to add a new switch
A22: 1 | B22: Products: type in the first empty row directly under the table - it auto-expands. Fill at minimum Product_ID, Model_Name, Family, Category, Status, port counts, PoE and PSU fields, Source_Datasheet.
A23: 2 | B23: Grey columns are formulas; if Excel doesn't auto-fill them, copy the formula from the row above.
A24: 3 | B24: SKUs: add one row per regional/TAA orderable SKU.
A25: 4 | B25: Accessories: add any new PSU/optic/support SKU. Compatibility: add Product- or Family-scoped rows (a Family row covers all its models).
A26: 4b | B26: New port speed (e.g. 50G): add a Ports_ column in Products next to the others and a matching row in Port_Types.
A27: 5 | B27: If the switch has modular PSUs, add its combinations to PSU_PoE_Matrix. Add any footnote constraint to Design_Rules.
A28: 6 | B28: Log conflicts in Data_Gaps and set Last_Verified.
A30: Conventions | B30: Units are in the column header (W, mm, kg, Gbps). Numbers stored as numbers; blank = not applicable / not stated. Never overwrite a datasheet value with an estimate - use Data_Notes.
A31: Legend | B31: Grey fill = calculated · Yellow fill = to be filled from price book / PLM · Blue text = user input in Model_Lookup
A32: Sources | B32: M4250: DS-M4250-9Nov23 · M4350: DS-M4350-30May25 (uploaded as 'M3450_Datasheet_30May25.pdf') · PR460X: NG_DS_AV_PR460X-042926 · WBE718: DS-WBE718_02Apr26 · WBE758: D-WBE758_29Jan24 · 25G/100G optics & DACs: optic.ca, NETGEAR KB 000066694 (updated 2025-09-23)
A34: Catalog counts
A35: Products | B35: =COUNTA(Products!A5:A1000)
A36: Orderable SKUs | B36: =COUNTA(SKUs!C5:C2000)
A37: Accessory SKUs | B37: =COUNTA(Accessories!A5:A2000)
A38: PSU configs | B38: =COUNTA(PSU_PoE_Matrix!A5:A2000)
A39: Open gaps | B39: =COUNTA(Data_Gaps!A5:A500)

Sheet Products
A1: NETGEAR BoM Catalog — Products (one row per base model)
A2: Grey = calculated (copy formula down for new rows) · Yellow = to fill from price book/PLM · Green band = attribute group · Key column: Product_ID
A3: Identity | H3: Commercial | L3: Physical | S3: Ports | AI3: PoE (PSE) | AP3: PoE (PD) | AS3: Power | BB3: Performance | BK3: Features | BT3: Environment | BY3: Commercial | CC3: Router | CG3: Wireless | CK3: Governance
A4: Product_ID | B4: Model_Name | C4: Family | D4: Product_Line | E4: Category | F4: Role | G4: Management | H4: Lifecycle_Status | I4: List_Price_USD | J4: Lead_Time_Wks | K4: EOS_Date | L4: Form_Factor | M4: Rack_Units | N4: Width_Class | O4: Width_mm | P4: Depth_mm | Q4: Height_mm | R4: Weight_kg | S4: Ports_1G_RJ45 | T4: Ports_2.5G_RJ45 | U4: Ports_10G_RJ45 | V4: Ports_SFP_1G | W4: Ports_SFP_2.5G | X4: Ports_SFP+_10G | Y4: Ports_SFP28_25G | Z4: Ports_QSFP28_100G | AA4: Ports_5G_RJ45 | AB4: Ports_SFP56_50G | AC4: Ports_QSFP56_200G | AD4: Ports_QSFPDD_400G | AE4: Ports_Combo_10G | AF4: Total_Ports | AG4: Max_1G_SFP_Modules | AH4: Port_Speed_Constraints | AI4: PoE_Ports | AJ4: PoE_Standard | AK4: PoE_Max_W_per_Port | AL4: PoE_Budget_Base_W | AM4: PoE_Budget_Max_W | AN4: PoE_Budget_Redundant_Max_W | AO4: PoE_Avg_W_per_Port_at_Max | AP4: PD_Max_Draw_W | AQ4: PD_Required_PoE | AR4: PD_Uplink_Speed | AS4: PSU_Type | AT4: PSU_Internal_W | AU4: PSU_Fixed_Qty | AV4: PSU_Modular_Slots | AW4: PSU_Compat_Group | AX4: Power_Idle_W | AY4: Power_Max_NoPoE_W | AZ4: Power_Max_FullPoE_W | BA4: Heat_Max_BTU_hr | BB4: Switching_Fabric_Gbps | BC4: Throughput_Mpps | BD4: Packet_Buffer_Mb | BE4: RAM_GB | BF4: CPU | BG4: MAC_Table | BH4: Max_VLANs | BI4: IGMP_Groups | BJ4: Max_LAGs | BK4: L3_Feature_Set | BL4: Stacking | BM4: Stack_Max_Units | BN4: AVB | BO4: PTP | BP4: SMPTE_ST2110 | BQ4: IGMP_Plus | BR4: Engage_Support | BS4: Insight_Support | BT4: OpTemp_Max_C | BU4: Airflow | BV4: Fan_Off_Mode | BW4: Acoustic_Quiet_25C_dBA | BX4: MTBF_25C_hours | BY4: Warranty | BZ4: Support_Category | CA4: TAA_SKU | CB4: Included_Subscription | CC4: WAN_Ports | CD4: WAN_Throughput | CE4: VPN_Capacity | CF4: Max_Clients | CG4: WiFi_Standard | CH4: WiFi_Streams | CI4: WiFi_Max_Gbps | CJ4: SSIDs | CK4: Source_Datasheet | CL4: Last_Verified | CM4: Data_Notes
A5: GSM4210PD | B5: M4250-9G1F-PoE+ | C5: M4250 | D5: NETGEAR AV Line | E5: Switch | F5: Access / Edge | G5: AV UI; Engage; IT Web GUI; CLI; SNMP | H5: Active | L5: Desktop | N5: Desktop | O5: 210 | P5: 140 | Q5: 40 | R5: 0.965 | S5: 9 | T5: 0 | U5: 0 | V5: 1 | W5: 0 | X5: 0 | Y5: 0 | Z5: 0 | AA5: 0 | AB5: 0 | AC5: 0 | AD5: 0 | AE5: 0 | AF5: =SUM(S5:AE5) | AI5: 8 | AJ5: 802.3at PoE+ | AK5: 30 | AL5: 110 | AM5: 110 | AO5: =IFERROR(AM5/AI5,"") | AS5: External adapter (130W, included) | AU5: 1 | AV5: 0 | AW5: None (fixed) | AX5: 6.4 | AY5: 9.88 | AZ5: 132.25 | BA5: =IF(MAX(AY5,AZ5)=0,"",ROUND(MAX(AY5,AZ5)*3.412,0)) | BB5: 20 | BC5: 14.88 | BD5: 16 | BE5: 2 | BF5: ARM A9 1.25GHz | BG5: 16384 | BH5: 4093 | BI5: 2K IPv4 / 2K IPv6 | BJ5: 8 x 8 ports | BK5: Lite L3 (static, RIP, PIM-SM/DM, DHCP server) | BL5: No | BN5: Yes (256 streams; not on LAG) | BO5: PTPv2 1-step E2E Transparent Clock | BP5: No | BQ5: Yes | BR5: Yes | BS5: No | BT5: 45 | BU5: Fanless | BV5: Fanless | BW5: 0 | BX5: 1020808 | BY5: ProSAFE Limited Lifetime HW; Lifetime NBD replacement | BZ5: Cat 2 | CA5: Not listed | CK5: M4250 datasheet DS-M4250-9Nov23 (fw 13.0.4) | CL5: 2026-09-27 | CM5: Throughput 14.88 Mpps (perf table) vs 14.80 Mpps (spec table) - verify
A6: GSM4210PX | B6: M4250-8G2XF-PoE+ | C6: M4250 | D6: NETGEAR AV Line | E6: Switch | F6: Access / Edge | G6: AV UI; Engage; IT Web GUI; CLI; SNMP | H6: Active | L6: Desktop | N6: Desktop | O6: 210 | P6: 140 | Q6: 40 | R6: 0.967 | S6: 8 | T6: 0 | U6: 0 | V6: 0 | W6: 0 | X6: 2 | Y6: 0 | Z6: 0 | AA6: 0 | AB6: 0 | AC6: 0 | AD6: 0 | AE6: 0 | AF6: =SUM(S6:AE6) | AI6: 8 | AJ6: 802.3at PoE+ | AK6: 30 | AL6: 220 | AM6: 220 | AO6: =IFERROR(AM6/AI6,"") | AS6: External adapter APS254W (included) | AU6: 1 | AV6: 0 | AW6: None (fixed) | AX6: 9.51 | AY6: 18.14 | AZ6: 257.9 | BA6: =IF(MAX(AY6,AZ6)=0,"",ROUND(MAX(AY6,AZ6)*3.412,0)) | BB6: 56 | BC6: 41.67 | BD6: 16 | BE6: 2 | BF6: ARM A9 1.25GHz | BG6: 16384 | BH6: 4093 | BI6: 2K IPv4 / 2K IPv6 | BJ6: 8 x 8 ports | BK6: Lite L3 (static, RIP, PIM-SM/DM, DHCP server) | BL6: No | BN6: Yes (256 streams; not on LAG) | BO6: PTPv2 1-step E2E Transparent Clock | BP6: No | BQ6: Yes | BR6: Yes | BS6: No | BT6: 45 | BU6: Side-to-side | BV6: Yes (up to 180W PoE, RJ45 only) | BW6: 19.3 | BX6: 1484652 | BY6: ProSAFE Limited Lifetime HW; Lifetime NBD replacement | BZ6: Cat 2 | CA6: Not listed | CK6: M4250 datasheet DS-M4250-9Nov23 (fw 13.0.4) | CL6: 2026-09-27
A7: GSM4212P | B7: M4250-10G2F-PoE+ | C7: M4250 | D7: NETGEAR AV Line | E7: Switch | F7: Access / Edge | G7: AV UI; Engage; IT Web GUI; CLI; SNMP | H7: Active | L7: 1U rack | M7: 1 | N7: Full width | O7: 440 | P7: 200 | Q7: 43.2 | R7: 2.85 | S7: 10 | T7: 0 | U7: 0 | V7: 2 | W7: 0 | X7: 0 | Y7: 0 | Z7: 0 | AA7: 0 | AB7: 0 | AC7: 0 | AD7: 0 | AE7: 0 | AF7: =SUM(S7:AE7) | AI7: 8 | AJ7: 802.3at PoE+ | AK7: 30 | AL7: 125 | AM7: 125 | AO7: =IFERROR(AM7/AI7,"") | AS7: Internal fixed (C14) | AU7: 1 | AV7: 0 | AW7: None (fixed) | AX7: 8.53 | AY7: 17.32 | AZ7: 163.9 | BA7: =IF(MAX(AY7,AZ7)=0,"",ROUND(MAX(AY7,AZ7)*3.412,0)) | BB7: 24 | BC7: 17.86 | BD7: 16 | BE7: 2 | BF7: ARM A9 1.25GHz | BG7: 16384 | BH7: 4093 | BI7: 2K IPv4 / 2K IPv6 | BJ7: 8 x 8 ports | BK7: Lite L3 (static, RIP, PIM-SM/DM, DHCP server) | BL7: No | BN7: Yes (256 streams; not on LAG) | BO7: PTPv2 1-step E2E Transparent Clock | BP7: No | BQ7: Yes | BR7: Yes | BS7: No | BT7: 45 | BU7: Side-to-side | BV7: Yes (up to 80W PoE) | BW7: 27.38 | BX7: 778769 | BY7: ProSAFE Limited Lifetime HW; Lifetime NBD replacement | BZ7: Cat 2 | CA7: Not listed | CK7: M4250 datasheet DS-M4250-9Nov23 (fw 13.0.4) | CL7: 2026-09-27
A8: GSM4212PX | B8: M4250-10G2XF-PoE+ | C8: M4250 | D8: NETGEAR AV Line | E8: Switch | F8: Access / Edge | G8: AV UI; Engage; IT Web GUI; CLI; SNMP | H8: Active | L8: 1U rack | M8: 1 | N8: Full width | O8: 440 | P8: 200 | Q8: 43.2 | R8: 2.9 | S8: 10 | T8: 0 | U8: 0 | V8: 0 | W8: 0 | X8: 2 | Y8: 0 | Z8: 0 | AA8: 0 | AB8: 0 | AC8: 0 | AD8: 0 | AE8: 0 | AF8: =SUM(S8:AE8) | AI8: 8 | AJ8: 802.3at PoE+ | AK8: 30 | AL8: 240 | AM8: 240 | AO8: =IFERROR(AM8/AI8,"") | AS8: Internal fixed (C14) | AU8: 1 | AV8: 0 | AW8: None (fixed) | AX8: 12.96 | AY8: 25 | AZ8: 306.4 | BA8: =IF(MAX(AY8,AZ8)=0,"",ROUND(MAX(AY8,AZ8)*3.412,0)) | BB8: 60 | BC8: 44.64 | BD8: 16 | BE8: 2 | BF8: ARM A9 1.25GHz | BG8: 16384 | BH8: 4093 | BI8: 2K IPv4 / 2K IPv6 | BJ8: 8 x 8 ports | BK8: Lite L3 (static, RIP, PIM-SM/DM, DHCP server) | BL8: No | BN8: Yes (256 streams; not on LAG) | BO8: PTPv2 1-step E2E Transparent Clock | BP8: No | BQ8: Yes | BR8: Yes | BS8: No | BT8: 45 | BU8: Side-to-side | BV8: Yes (up to 90W PoE) | BW8: 27.4 | BX8: 576889 | BY8: ProSAFE Limited Lifetime HW; Lifetime NBD replacement | BZ8: Cat 2 | CA8: Not listed | CK8: M4250 datasheet DS-M4250-9Nov23 (fw 13.0.4) | CL8: 2026-09-27
A9: GSM4212UX | B9: M4250-10G2XF-PoE++ | C9: M4250 | D9: NETGEAR AV Line | E9: Switch | F9: Access / Edge | G9: AV UI; Engage; IT Web GUI; CLI; SNMP | H9: Active | L9: 1U rack | M9: 1 | N9: Full width | O9: 440 | P9: 257 | Q9: 43.2 | R9: 3.83 | S9: 10 | T9: 0 | U9: 0 | V9: 0 | W9: 0 | X9: 2 | Y9: 0 | Z9: 0 | AA9: 0 | AB9: 0 | AC9: 0 | AD9: 0 | AE9: 0 | AF9: =SUM(S9:AE9) | AI9: 8 | AJ9: 802.3bt Ultra90 PoE++ | AK9: 90 | AL9: 720 | AM9: 720 | AO9: =IFERROR(AM9/AI9,"") | AS9: Internal fixed (C14) | AU9: 1 | AV9: 0 | AW9: None (fixed) | AX9: 18 | AY9: 26.3 | AZ9: 837.7 | BA9: =IF(MAX(AY9,AZ9)=0,"",ROUND(MAX(AY9,AZ9)*3.412,0)) | BB9: 60 | BC9: 44.64 | BD9: 16 | BE9: 2 | BF9: ARM A9 1.25GHz | BG9: 16384 | BH9: 4093 | BI9: 2K IPv4 / 2K IPv6 | BJ9: 8 x 8 ports | BK9: Lite L3 (static, RIP, PIM-SM/DM, DHCP server) | BL9: No | BN9: Yes (256 streams; not on LAG) | BO9: PTPv2 1-step E2E Transparent Clock | BP9: No | BQ9: Yes | BR9: Yes | BS9: No | BT9: 45 | BU9: Side-to-side | BV9: Yes (up to 45W PoE) | BW9: 34.57 | BX9: 947871 | BY9: ProSAFE Limited Lifetime HW; Lifetime NBD replacement | BZ9: Cat 2 | CA9: Not listed | CK9: M4250 datasheet DS-M4250-9Nov23 (fw 13.0.4) | CL9: 2026-09-27
A10: GSM4230P | B10: M4250-26G4F-PoE+ | C10: M4250 | D10: NETGEAR AV Line | E10: Switch | F10: Access / Edge | G10: AV UI; Engage; IT Web GUI; CLI; SNMP | H10: Active | L10: 1U rack | M10: 1 | N10: Full width | O10: 440 | P10: 257 | Q10: 43.2 | R10: 4.3 | S10: 26 | T10: 0 | U10: 0 | V10: 4 | W10: 0 | X10: 0 | Y10: 0 | Z10: 0 | AA10: 0 | AB10: 0 | AC10: 0 | AD10: 0 | AE10: 0 | AF10: =SUM(S10:AE10) | AI10: 24 | AJ10: 802.3at PoE+ | AK10: 30 | AL10: 300 | AM10: 300 | AO10: =IFERROR(AM10/AI10,"") | AS10: Internal fixed (C14) | AU10: 1 | AV10: 0 | AW10: None (fixed) | AX10: 23.4 | AY10: 35.8 | AZ10: 401 | BA10: =IF(MAX(AY10,AZ10)=0,"",ROUND(MAX(AY10,AZ10)*3.412,0)) | BB10: 60 | BC10: 44.64 | BD10: 16 | BE10: 2 | BF10: Quad-core Cortex-A57 1.8GHz | BG10: 16384 | BH10: 4093 | BI10: 2K IPv4 / 2K IPv6 | BJ10: 8 x 8 ports | BK10: Lite L3 (static, RIP, PIM-SM/DM, DHCP server) | BL10: No | BN10: Yes (256 streams; not on LAG) | BO10: PTPv2 1-step E2E Transparent Clock | BP10: No | BQ10: Yes | BR10: Yes | BS10: No | BT10: 45 | BU10: Side-to-side | BV10: Yes (up to 45W PoE, 8 ports) | BW10: 28 | BX10: 511054 | BY10: ProSAFE Limited Lifetime HW; Lifetime NBD replacement | BZ10: Cat 2 | CA10: Not listed | CK10: M4250 datasheet DS-M4250-9Nov23 (fw 13.0.4) | CL10: 2026-09-27
A11: GSM4230UP | B11: M4250-26G4F-PoE++ | C11: M4250 | D11: NETGEAR AV Line | E11: Switch | F11: Access / Edge | G11: AV UI; Engage; IT Web GUI; CLI; SNMP | H11: Active | L11: 1U rack | M11: 1 | N11: Full width | O11: 440 | P11: 400 | Q11: 43.2 | R11: 6.746 | S11: 26 | T11: 0 | U11: 0 | V11: 4 | W11: 0 | X11: 0 | Y11: 0 | Z11: 0 | AA11: 0 | AB11: 0 | AC11: 0 | AD11: 0 | AE11: 0 | AF11: =SUM(S11:AE11) | AI11: 24 | AJ11: 802.3bt Ultra90 PoE++ | AK11: 90 | AL11: 720 | AM11: 1440 | AO11: =IFERROR(AM11/AI11,"") | AS11: 2x internal fixed (C14), RPS/EPS | AU11: 2 | AV11: 0 | AW11: None (fixed) | AX11: 36.9 | AY11: 48.8 | AZ11: 1734 | BA11: =IF(MAX(AY11,AZ11)=0,"",ROUND(MAX(AY11,AZ11)*3.412,0)) | BB11: 60 | BC11: 44.64 | BD11: 16 | BE11: 2 | BF11: Quad-core Cortex-A57 1.8GHz | BG11: 16384 | BH11: 4093 | BI11: 2K IPv4 / 2K IPv6 | BJ11: 8 x 8 ports | BK11: Lite L3 (static, RIP, PIM-SM/DM, DHCP server) | BL11: No | BN11: Yes (256 streams; not on LAG) | BO11: PTPv2 1-step E2E Transparent Clock | BP11: No | BQ11: Yes | BR11: Yes | BS11: No | BT11: 45 | BU11: Side-to-side | BV11: No | BW11: 28 | BX11: 491282 | BY11: ProSAFE Limited Lifetime HW; Lifetime NBD replacement | BZ11: Cat 3 | CA11: Not listed | CK11: M4250 datasheet DS-M4250-9Nov23 (fw 13.0.4) | CL11: 2026-09-27 | CM11: PoE budget 720W with 1 PSU powered, 1,440W with 2. Full-PoE power: 889W (1 PSU) / 1,734W (2 PSU)
A12: GSM4230PX | B12: M4250-26G4XF-PoE+ | C12: M4250 | D12: NETGEAR AV Line | E12: Switch | F12: Access / Edge | G12: AV UI; Engage; IT Web GUI; CLI; SNMP | H12: Active | L12: 1U rack | M12: 1 | N12: Full width | O12: 440 | P12: 400 | Q12: 43.2 | R12: 5.453 | S12: 26 | T12: 0 | U12: 0 | V12: 0 | W12: 0 | X12: 4 | Y12: 0 | Z12: 0 | AA12: 0 | AB12: 0 | AC12: 0 | AD12: 0 | AE12: 0 | AF12: =SUM(S12:AE12) | AI12: 24 | AJ12: 802.3at PoE+ | AK12: 30 | AL12: 480 | AM12: 480 | AO12: =IFERROR(AM12/AI12,"") | AS12: Internal fixed (C14) | AU12: 1 | AV12: 0 | AW12: None (fixed) | AX12: 33.9 | AY12: 46.8 | AZ12: 614 | BA12: =IF(MAX(AY12,AZ12)=0,"",ROUND(MAX(AY12,AZ12)*3.412,0)) | BB12: 132 | BC12: 98.21 | BD12: 16 | BE12: 2 | BF12: Quad-core Cortex-A57 1.8GHz | BG12: 16384 | BH12: 4093 | BI12: 2K IPv4 / 2K IPv6 | BJ12: 8 x 8 ports | BK12: Lite L3 (static, RIP, PIM-SM/DM, DHCP server) | BL12: No | BN12: Yes (256 streams; not on LAG) | BO12: PTPv2 1-step E2E Transparent Clock | BP12: No | BQ12: Yes | BR12: Yes | BS12: No | BT12: 45 | BU12: Side-to-side | BV12: Yes (up to 45W PoE, 8 ports) | BW12: 25 | BX12: 509057 | BY12: ProSAFE Limited Lifetime HW; Lifetime NBD replacement | BZ12: Cat 3 | CA12: Not listed | CK12: M4250 datasheet DS-M4250-9Nov23 (fw 13.0.4) | CL12: 2026-09-27
A13: GSM4248P | B13: M4250-40G8F-PoE+ | C13: M4250 | D13: NETGEAR AV Line | E13: Switch | F13: Access / Edge | G13: AV UI; Engage; IT Web GUI; CLI; SNMP | H13: Active | L13: 1U rack | M13: 1 | N13: Full width | O13: 440 | P13: 400 | Q13: 43.2 | R13: 5.852 | S13: 40 | T13: 0 | U13: 0 | V13: 8 | W13: 0 | X13: 0 | Y13: 0 | Z13: 0 | AA13: 0 | AB13: 0 | AC13: 0 | AD13: 0 | AE13: 0 | AF13: =SUM(S13:AE13) | AI13: 40 | AJ13: 802.3at PoE+ | AK13: 30 | AL13: 480 | AM13: 480 | AO13: =IFERROR(AM13/AI13,"") | AS13: Internal fixed (C14) | AU13: 1 | AV13: 0 | AW13: None (fixed) | AX13: 46.4 | AY13: 59.5 | AZ13: 624.8 | BA13: =IF(MAX(AY13,AZ13)=0,"",ROUND(MAX(AY13,AZ13)*3.412,0)) | BB13: 96 | BC13: 71.42 | BD13: 32 | BE13: 2 | BF13: Quad-core Cortex-A57 1.8GHz | BG13: 16384 | BH13: 4093 | BI13: 2K IPv4 / 2K IPv6 | BJ13: 8 x 8 ports | BK13: Lite L3 (static, RIP, PIM-SM/DM, DHCP server) | BL13: No | BN13: Yes (256 streams; not on LAG) | BO13: PTPv2 1-step E2E Transparent Clock | BP13: No | BQ13: Yes | BR13: Yes | BS13: No | BT13: 45 | BU13: Side-to-side | BV13: Yes (up to 30W PoE, 8 ports) | BW13: 30 | BX13: 341680 | BY13: ProSAFE Limited Lifetime HW; Lifetime NBD replacement | BZ13: Cat 3 | CA13: Not listed | CK13: M4250 datasheet DS-M4250-9Nov23 (fw 13.0.4) | CL13: 2026-09-27
A14: GSM4248PX | B14: M4250-40G8XF-PoE+ | C14: M4250 | D14: NETGEAR AV Line | E14: Switch | F14: Access / Edge | G14: AV UI; Engage; IT Web GUI; CLI; SNMP | H14: Active | L14: 1U rack | M14: 1 | N14: Full width | O14: 440 | P14: 400 | Q14: 43.2 | R14: 6.312 | S14: 40 | T14: 0 | U14: 0 | V14: 0 | W14: 0 | X14: 8 | Y14: 0 | Z14: 0 | AA14: 0 | AB14: 0 | AC14: 0 | AD14: 0 | AE14: 0 | AF14: =SUM(S14:AE14) | AI14: 40 | AJ14: 802.3at PoE+ | AK14: 30 | AL14: 960 | AM14: 960 | AO14: =IFERROR(AM14/AI14,"") | AS14: Internal fixed (C14) | AU14: 1 | AV14: 0 | AW14: None (fixed) | AX14: 74.5 | AY14: 89.2 | AZ14: 1197 | BA14: =IF(MAX(AY14,AZ14)=0,"",ROUND(MAX(AY14,AZ14)*3.412,0)) | BB14: 240 | BC14: 178.56 | BD14: 32 | BE14: 2 | BF14: Quad-core Cortex-A57 1.8GHz | BG14: 16384 | BH14: 4093 | BI14: 2K IPv4 / 2K IPv6 | BJ14: 8 x 8 ports | BK14: Lite L3 (static, RIP, PIM-SM/DM, DHCP server) | BL14: No | BN14: Yes (256 streams; not on LAG) | BO14: PTPv2 1-step E2E Transparent Clock | BP14: No | BQ14: Yes | BR14: Yes | BS14: No | BT14: 45 | BU14: Side-to-side | BV14: No | BW14: 29 | BX14: 487900 | BY14: ProSAFE Limited Lifetime HW; Lifetime NBD replacement | BZ14: Cat 3 | CA14: Not listed | CK14: M4250 datasheet DS-M4250-9Nov23 (fw 13.0.4) | CL14: 2026-09-27
A15: GSM4248UX | B15: M4250-40G8XF-PoE++ | C15: M4250 | D15: NETGEAR AV Line | E15: Switch | F15: Access / Edge | G15: AV UI; Engage; IT Web GUI; CLI; SNMP | H15: Active | L15: 2U rack | M15: 2 | N15: Full width | O15: 440 | P15: 350 | Q15: 86.4 | R15: 10.28 | S15: 40 | T15: 0 | U15: 0 | V15: 0 | W15: 0 | X15: 8 | Y15: 0 | Z15: 0 | AA15: 0 | AB15: 0 | AC15: 0 | AD15: 0 | AE15: 0 | AF15: =SUM(S15:AE15) | AI15: 40 | AJ15: 802.3bt Ultra90 PoE++ | AK15: 90 | AL15: 720 | AM15: 2880 | AO15: =IFERROR(AM15/AI15,"") | AS15: 3x internal fixed (C14), RPS/EPS | AU15: 3 | AV15: 0 | AW15: None (fixed) | AX15: 68.5 | AY15: 82.6 | AZ15: 3523 | BA15: =IF(MAX(AY15,AZ15)=0,"",ROUND(MAX(AY15,AZ15)*3.412,0)) | BB15: 240 | BC15: 178.56 | BD15: 32 | BE15: 2 | BF15: Quad-core Cortex-A57 1.8GHz | BG15: 16384 | BH15: 4093 | BI15: 2K IPv4 / 2K IPv6 | BJ15: 8 x 8 ports | BK15: Lite L3 (static, RIP, PIM-SM/DM, DHCP server) | BL15: No | BN15: Yes (256 streams; not on LAG) | BO15: PTPv2 1-step E2E Transparent Clock | BP15: No | BQ15: Yes | BR15: Yes | BS15: No | BT15: 45 | BU15: Side-to-side | BV15: No | BW15: 30 | BX15: 304916 | BY15: ProSAFE Limited Lifetime HW; Lifetime NBD replacement | BZ15: Cat 3 | CA15: Not listed | CK15: M4250 datasheet DS-M4250-9Nov23 (fw 13.0.4) | CL15: 2026-09-27 | CM15: PoE budget 720W (1 PSU) / 1,650W (2 PSU) / 2,880W (3 PSU). Full-PoE power: 912 / 1,998 / 3,523W
A16: MSM4214X | B16: M4250-12M2XF | C16: M4250 | D16: NETGEAR AV Line | E16: Switch | F16: Aggregation | G16: AV UI; Engage; IT Web GUI; CLI; SNMP | H16: Active | L16: 1U rack | M16: 1 | N16: Full width | O16: 440 | P16: 100 | Q16: 43.2 | R16: 1.745 | S16: 0 | T16: 12 | U16: 0 | V16: 0 | W16: 0 | X16: 2 | Y16: 0 | Z16: 0 | AA16: 0 | AB16: 0 | AC16: 0 | AD16: 0 | AE16: 0 | AF16: =SUM(S16:AE16) | AI16: 0 | AJ16: None | AO16: =IFERROR(AM16/AI16,"") | AS16: Internal fixed (C14) | AU16: 1 | AV16: 0 | AW16: None (fixed) | AX16: 14.1 | AY16: 37.9 | BA16: =IF(MAX(AY16,AZ16)=0,"",ROUND(MAX(AY16,AZ16)*3.412,0)) | BB16: 100 | BC16: 74.4 | BD16: 16 | BE16: 2 | BF16: ARM A9 1.25GHz | BG16: 16384 | BH16: 4093 | BI16: 2K IPv4 / 2K IPv6 | BJ16: 8 x 8 ports | BK16: Lite L3 (static, RIP, PIM-SM/DM, DHCP server) | BL16: No | BN16: Yes (256 streams; not on LAG) | BO16: PTPv2 1-step E2E Transparent Clock | BP16: No | BQ16: Yes | BR16: Yes | BS16: No | BT16: 50 | BU16: Side-to-side | BV16: Yes (8x2.5G, no SFP+) | BW16: 28.5 | BX16: 720892 | BY16: ProSAFE Limited Lifetime HW; Lifetime NBD replacement | BZ16: Cat 2 | CA16: Not listed | CK16: M4250 datasheet DS-M4250-9Nov23 (fw 13.0.4) | CL16: 2026-09-27
A17: XSM4216F | B17: M4250-16XF | C17: M4250 | D17: NETGEAR AV Line | E17: Switch | F17: Aggregation | G17: AV UI; Engage; IT Web GUI; CLI; SNMP | H17: Active | L17: 1U rack | M17: 1 | N17: Full width | O17: 440 | P17: 200 | Q17: 43.2 | R17: 2.8 | S17: 0 | T17: 0 | U17: 0 | V17: 0 | W17: 0 | X17: 16 | Y17: 0 | Z17: 0 | AA17: 0 | AB17: 0 | AC17: 0 | AD17: 0 | AE17: 0 | AF17: =SUM(S17:AE17) | AG17: 12 | AH17: 1G SFP only on ports 1-12 | AI17: 0 | AJ17: None | AO17: =IFERROR(AM17/AI17,"") | AS17: Internal fixed (C14) | AU17: 1 | AV17: 0 | AW17: None (fixed) | AX17: 19.27 | AY17: 47.84 | BA17: =IF(MAX(AY17,AZ17)=0,"",ROUND(MAX(AY17,AZ17)*3.412,0)) | BB17: 320 | BC17: 238.08 | BD17: 16 | BE17: 2 | BF17: ARM A9 1.25GHz | BG17: 16384 | BH17: 4093 | BI17: 2K IPv4 / 2K IPv6 | BJ17: 8 x 8 ports | BK17: Lite L3 (static, RIP, PIM-SM/DM, DHCP server) | BL17: No | BN17: Yes (256 streams; not on LAG) | BO17: PTPv2 1-step E2E Transparent Clock | BP17: No | BQ17: Yes | BR17: Yes | BS17: No | BT17: 50 | BU17: Side-to-side | BV17: Yes (8x SFP+) | BW17: 27.44 | BX17: 844633 | BY17: ProSAFE Limited Lifetime HW; Lifetime NBD replacement | BZ17: Cat 2 | CA17: Not listed | CK17: M4250 datasheet DS-M4250-9Nov23 (fw 13.0.4) | CL17: 2026-09-27 | CM17: Weight: 1.74 kg on product page vs 2.80 kg in spec table - verify
A18: GSM4328 | B18: M4350-24G4XF | C18: M4350 | D18: NETGEAR AV and IT | E18: Switch | F18: Access / Edge | G18: AV UI; Engage; IT Web GUI; CLI; SNMP | H18: Active | L18: 1U rack | M18: 1 | N18: Full width | O18: 440 | P18: 400 | Q18: 43.2 | R18: 6.41 | S18: 24 | T18: 0 | U18: 0 | V18: 0 | W18: 0 | X18: 4 | Y18: 0 | Z18: 0 | AA18: 0 | AB18: 0 | AC18: 0 | AD18: 0 | AE18: 0 | AF18: =SUM(S18:AE18) | AI18: 24 | AJ18: 802.3at PoE+ | AK18: 30 | AL18: 648 | AM18: 720 | AN18: 648 | AO18: =IFERROR(AM18/AI18,"") | AS18: Internal fixed + modular slots | AT18: 880 | AU18: 1 | AV18: 1 | AW18: A: APS350W / APS600Wv2 / APS920W / APS2000W | AX18: 32 | AY18: 80 | AZ18: 871.2 | BA18: =IF(MAX(AY18,AZ18)=0,"",ROUND(MAX(AY18,AZ18)*3.412,0)) | BB18: 128 | BC18: 95.23 | BD18: 16 | BE18: 2 | BF18: Quad-core Cortex-A57 1.8GHz | BG18: 16384 | BH18: 4093 | BI18: 2K IPv4 / 2K IPv6 | BK18: Full L3 (static, RIP, OSPF, VRRP, PIM-SM/DM, PBR) | BL18: Yes (NSF) | BM18: 8 | BN18: Yes (exclusive with stacking) | BO18: PTPv2 1-step E2E Transparent Clock | BP18: No | BQ18: Yes | BR18: Yes | BS18: No | BT18: 45 | BU18: Front-to-back | BV18: No (Quiet / Cool modes) | BW18: 33 | BX18: 782376 | BY18: ProSAFE Limited Lifetime HW; Lifetime NBD replacement | BZ18: Cat 3 | CA18: Not listed | CK18: M4350 datasheet DS-M4350-30May25 (fw 14.0) [file: M3450_Datasheet_30May25.pdf] | CL18: 2026-09-27
A19: GSM4352 | B19: M4350-48G4XF | C19: M4350 | D19: NETGEAR AV and IT | E19: Switch | F19: Access / Edge | G19: AV UI; Engage; IT Web GUI; CLI; SNMP | H19: Active | L19: 1U rack | M19: 1 | N19: Full width | O19: 440 | P19: 400 | Q19: 43.2 | R19: 7.19 | S19: 48 | T19: 0 | U19: 0 | V19: 0 | W19: 0 | X19: 4 | Y19: 0 | Z19: 0 | AA19: 0 | AB19: 0 | AC19: 0 | AD19: 0 | AE19: 0 | AF19: =SUM(S19:AE19) | AI19: 48 | AJ19: 802.3at PoE+ | AK19: 30 | AL19: 236 | AM19: 1440 | AN19: 1440 | AO19: =IFERROR(AM19/AI19,"") | AS19: Internal fixed + modular slots | AT19: 550 | AU19: 1 | AV19: 2 | AW19: A: APS350W / APS600Wv2 / APS920W / APS2000W | AX19: 48.5 | AY19: 99 | AZ19: 1618.3 | BA19: =IF(MAX(AY19,AZ19)=0,"",ROUND(MAX(AY19,AZ19)*3.412,0)) | BB19: 176 | BC19: 130.94 | BD19: 32 | BE19: 2 | BF19: Quad-core Cortex-A57 1.8GHz | BG19: 16384 | BH19: 4093 | BI19: 2K IPv4 / 2K IPv6 | BK19: Full L3 (static, RIP, OSPF, VRRP, PIM-SM/DM, PBR) | BL19: Yes (NSF) | BM19: 8 | BN19: Yes (exclusive with stacking) | BO19: PTPv2 1-step E2E Transparent Clock | BP19: No | BQ19: Yes | BR19: Yes | BS19: No | BT19: 45 | BU19: Front-to-back | BV19: No (Quiet / Cool modes) | BW19: 33 | BX19: 623591 | BY19: ProSAFE Limited Lifetime HW; Lifetime NBD replacement | BZ19: Cat 3 | CA19: Not listed | CK19: M4350 datasheet DS-M4350-30May25 (fw 14.0) [file: M3450_Datasheet_30May25.pdf] | CL19: 2026-09-27
A20: MSM4310 | B20: M4350-8M2V | C20: M4350 | D20: NETGEAR AV and IT | E20: Switch | F20: Access / Edge | G20: AV UI; Engage; IT Web GUI; CLI; SNMP | H20: Active | L20: 1U rack | M20: 1 | N20: Half width | O20: 220 | P20: 300 | Q20: 43.2 | R20: 2.9 | S20: 0 | T20: 8 | U20: 0 | V20: 0 | W20: 0 | X20: 0 | Y20: 2 | Z20: 0 | AA20: 0 | AB20: 0 | AC20: 0 | AD20: 0 | AE20: 0 | AF20: =SUM(S20:AE20) | AH20: SFP28 ports 9-10: 10G or 25G only | AI20: 8 | AJ20: 802.3bt Ultra90 PoE++ | AK20: 90 | AL20: 119 | AM20: 551 | AN20: 322 | AO20: =IFERROR(AM20/AI20,"") | AS20: External adapter APS254W (1 incl., 3 DC inputs) | AT20: 254 | AU20: 1 | AV20: 2 | AW20: APS254W (external DC, up to 3 total) | AX20: 61.2 | AY20: 82 | AZ20: 682 | BA20: =IF(MAX(AY20,AZ20)=0,"",ROUND(MAX(AY20,AZ20)*3.412,0)) | BB20: 140 | BC20: 104.16 | BD20: 32 | BE20: 4 | BF20: Quad-core Cortex-A57 1.8GHz | BG20: 16384 | BH20: 4093 | BI20: 2K IPv4 / 2K IPv6 | BK20: Full L3 (static, RIP, OSPF, VRRP, PIM-SM/DM, PBR) | BL20: Yes (NSF) | BM20: 8 | BN20: Yes (exclusive with stacking) | BO20: PTPv2 TC + Boundary/Grandmaster (SMPTE 2059-2, AES67, AES-R16) | BP20: Yes | BQ20: Yes | BR20: Yes | BS20: No | BT20: 45 | BU20: Front-to-back | BV20: No (Quiet / Cool modes) | BW20: 32.2 | BX20: 415986 | BY20: ProSAFE Limited Lifetime HW; Lifetime NBD replacement | BZ20: Cat 3 | CA20: Yes (-TAANES) | CK20: M4350 datasheet DS-M4350-30May25 (fw 14.0) [file: M3450_Datasheet_30May25.pdf] | CL20: 2026-09-27 | CM20: Ships with 1x APS254W. Redundant budget 119W (1+1) or 322W (2+1). Optional PST4310 half-width PSU tray.
A21: MSM4332 | B21: M4350-24M4X4V | C21: M4350 | D21: NETGEAR AV and IT | E21: Switch | F21: Access / Edge | G21: AV UI; Engage; IT Web GUI; CLI; SNMP | H21: Active | L21: 1U rack | M21: 1 | N21: Full width | O21: 440 | P21: 400 | Q21: 43.2 | R21: 7.38 | S21: 0 | T21: 24 | U21: 4 | V21: 0 | W21: 0 | X21: 0 | Y21: 4 | Z21: 0 | AA21: 0 | AB21: 0 | AC21: 0 | AD21: 0 | AE21: 0 | AF21: =SUM(S21:AE21) | AH21: 10G RJ45 ports: 1/2.5/5/10G only (no 100M). SFP28 29-32: 10G or 25G only | AI21: 28 | AJ21: 802.3bt Ultra90 PoE++ | AK21: 90 | AL21: 522 | AM21: 2520 | AN21: 1972 | AO21: =IFERROR(AM21/AI21,"") | AS21: Internal fixed + modular slots | AT21: 800 | AU21: 1 | AV21: 2 | AW21: B: APS600Wv3 / APS1200Wv2 / APS2000Wv2 | AX21: 53 | AY21: 123.4 | AZ21: 2845 | BA21: =IF(MAX(AY21,AZ21)=0,"",ROUND(MAX(AY21,AZ21)*3.412,0)) | BB21: 400 | BC21: 297.6 | BD21: 32 | BE21: 4 | BF21: Quad-core Cortex-A57 1.8GHz | BG21: 16384 | BH21: 4093 | BI21: 2K IPv4 / 2K IPv6 | BK21: Full L3 (static, RIP, OSPF, VRRP, PIM-SM/DM, PBR) | BL21: Yes (NSF) | BM21: 8 | BN21: Yes (exclusive with stacking) | BO21: PTPv2 TC + Boundary/Grandmaster (SMPTE 2059-2, AES67, AES-R16) | BP21: Yes | BQ21: Yes | BR21: Yes | BS21: No | BT21: 45 | BU21: Front-to-back | BV21: No (Quiet / Cool modes) | BW21: 34.8 | BX21: 377861 | BY21: ProSAFE Limited Lifetime HW; Lifetime NBD replacement | BZ21: Cat 3 | CA21: Yes (-TAANES) | CK21: M4350 datasheet DS-M4350-30May25 (fw 14.0) [file: M3450_Datasheet_30May25.pdf] | CL21: 2026-09-27
A22: MSM4352 | B22: M4350-44M4X4V | C22: M4350 | D22: NETGEAR AV and IT | E22: Switch | F22: Access / Edge | G22: AV UI; Engage; IT Web GUI; CLI; SNMP | H22: Active | L22: 1U rack | M22: 1 | N22: Full width | O22: 440 | P22: 400 | Q22: 43.2 | R22: 7.34 | S22: 0 | T22: 44 | U22: 4 | V22: 0 | W22: 0 | X22: 0 | Y22: 4 | Z22: 0 | AA22: 0 | AB22: 0 | AC22: 0 | AD22: 0 | AE22: 0 | AF22: =SUM(S22:AE22) | AH22: 100M only on ports 1-44; 10G RJ45 no 100M. SFP28 49-52: 10G or 25G only | AI22: 48 | AJ22: 802.3bt Ultra90 PoE++ | AK22: 90 | AL22: 194 | AM22: 3314 | AN22: 1794 | AO22: =IFERROR(AM22/AI22,"") | AS22: Internal fixed + modular slots | AT22: 550 | AU22: 1 | AV22: 2 | AW22: A: APS350W / APS600Wv2 / APS920W / APS2000W | AX22: 56.5 | AY22: 133.5 | AZ22: 3857.5 | BA22: =IF(MAX(AY22,AZ22)=0,"",ROUND(MAX(AY22,AZ22)*3.412,0)) | BB22: 500 | BC22: 372 | BD22: 32 | BE22: 2 | BF22: Quad-core Cortex-A57 1.8GHz | BG22: 16384 | BH22: 4093 | BI22: 2K IPv4 / 2K IPv6 | BK22: Full L3 (static, RIP, OSPF, VRRP, PIM-SM/DM, PBR) | BL22: Yes (NSF) | BM22: 8 | BN22: Yes (exclusive with stacking) | BO22: PTPv2 1-step E2E Transparent Clock | BP22: No | BQ22: Yes | BR22: Yes | BS22: No | BT22: 45 | BU22: Front-to-back | BV22: No (Quiet / Cool modes) | BW22: 34 | BX22: 320552 | BY22: ProSAFE Limited Lifetime HW; Lifetime NBD replacement | BZ22: Cat 3 | CA22: Yes (-TAANES) | CK22: M4350 datasheet DS-M4350-30May25 (fw 14.0) [file: M3450_Datasheet_30May25.pdf] | CL22: 2026-09-27 | CM22: Max 3,314W PoE needs 2x APS2000W on 220VAC
A23: MSM4328F | B23: M4350-24F4X | C23: M4350 | D23: NETGEAR AV and IT | E23: Switch | F23: Aggregation / Core | G23: AV UI; Engage; IT Web GUI; CLI; SNMP | H23: Active | L23: 1U rack | M23: 1 | N23: Full width | O23: 440 | P23: 400 | Q23: 43.2 | R23: 7.38 | S23: 0 | T23: 0 | U23: 0 | V23: 0 | W23: 24 | X23: 0 | Y23: 0 | Z23: 0 | AA23: 0 | AB23: 0 | AC23: 0 | AD23: 0 | AE23: 4 | AF23: =SUM(S23:AE23) | AH23: 24x SFP 1G/2.5G only; 4 combo 10GBASE-T / SFP+ (SFP+ side 1G/10G only) | AI23: 0 | AJ23: None | AO23: =IFERROR(AM23/AI23,"") | AS23: Internal fixed + modular slots | AT23: 240 | AU23: 1 | AV23: 1 | AW23: B: APS600Wv3 / APS1200Wv2 / APS2000Wv2 | AX23: 39 | AY23: 115.5 | BA23: =IF(MAX(AY23,AZ23)=0,"",ROUND(MAX(AY23,AZ23)*3.412,0)) | BB23: 200 | BC23: 148.8 | BD23: 32 | BE23: 4 | BF23: Quad-core Cortex-A57 1.8GHz | BG23: 16384 | BH23: 4093 | BI23: 2K IPv4 / 2K IPv6 | BK23: Full L3 (static, RIP, OSPF, VRRP, PIM-SM/DM, PBR) | BL23: Yes (NSF) | BM23: 8 | BN23: Yes (exclusive with stacking) | BO23: PTPv2 TC + Boundary/Grandmaster (SMPTE 2059-2, AES67, AES-R16) | BP23: Yes | BQ23: Yes | BR23: Yes | BS23: No | BT23: 50 | BU23: Front-to-back | BV23: No (Quiet / Cool modes) | BW23: 30 | BX23: 795845 | BY23: ProSAFE Limited Lifetime HW; Lifetime NBD replacement | BZ23: Cat 3 | CA23: Yes (-TAANES) | CK23: M4350 datasheet DS-M4350-30May25 (fw 14.0) [file: M3450_Datasheet_30May25.pdf] | CL23: 2026-09-27 | CM23: Modular slot = RPS only (no PoE)
A24: XSM4316 | B24: M4350-8X8F | C24: M4350 | D24: NETGEAR AV and IT | E24: Switch | F24: Aggregation / Core | G24: AV UI; Engage; IT Web GUI; CLI; SNMP | H24: Active | L24: 1U rack | M24: 1 | N24: Half width | O24: 220 | P24: 400 | Q24: 43.2 | R24: 4.05 | S24: 0 | T24: 0 | U24: 8 | V24: 0 | W24: 0 | X24: 8 | Y24: 0 | Z24: 0 | AA24: 0 | AB24: 0 | AC24: 0 | AD24: 0 | AE24: 0 | AF24: =SUM(S24:AE24) | AH24: 1G on copper 1-8 and SFP+ 9-12 only | AI24: 0 | AJ24: None | AO24: =IFERROR(AM24/AI24,"") | AS24: Internal fixed (C14) | AT24: 240 | AU24: 1 | AV24: 0 | AW24: None (fixed) | AX24: 30.5 | AY24: 81.1 | BA24: =IF(MAX(AY24,AZ24)=0,"",ROUND(MAX(AY24,AZ24)*3.412,0)) | BB24: 320 | BC24: 238.08 | BD24: 32 | BE24: 2 | BF24: Quad-core Cortex-A57 1.8GHz | BG24: 16384 | BH24: 4093 | BI24: 2K IPv4 / 2K IPv6 | BK24: Full L3 (static, RIP, OSPF, VRRP, PIM-SM/DM, PBR) | BL24: Yes (NSF) | BM24: 8 | BN24: Yes (exclusive with stacking) | BO24: PTPv2 1-step E2E Transparent Clock | BP24: No | BQ24: Yes | BR24: Yes | BS24: No | BT24: 50 | BU24: Front-to-back | BV24: No (Quiet / Cool modes) | BW24: 34.43 | BX24: 1101630 | BY24: ProSAFE Limited Lifetime HW; Lifetime NBD replacement | BZ24: Cat 3 | CA24: Not listed | CK24: M4350 datasheet DS-M4350-30May25 (fw 14.0) [file: M3450_Datasheet_30May25.pdf] | CL24: 2026-09-27
A25: XSM4324 | B25: M4350-12X12F | C25: M4350 | D25: NETGEAR AV and IT | E25: Switch | F25: Aggregation / Core | G25: AV UI; Engage; IT Web GUI; CLI; SNMP | H25: Active | L25: 1U rack | M25: 1 | N25: Half width | O25: 220 | P25: 400 | Q25: 43.2 | R25: 4.3 | S25: 0 | T25: 0 | U25: 12 | V25: 0 | W25: 0 | X25: 12 | Y25: 0 | Z25: 0 | AA25: 0 | AB25: 0 | AC25: 0 | AD25: 0 | AE25: 0 | AF25: =SUM(S25:AE25) | AH25: 1G on copper 1-12 and SFP+ 13-20 only | AI25: 0 | AJ25: None | AO25: =IFERROR(AM25/AI25,"") | AS25: Internal fixed (C14) | AT25: 240 | AU25: 1 | AV25: 0 | AW25: None (fixed) | AX25: 34 | AY25: 95.8 | BA25: =IF(MAX(AY25,AZ25)=0,"",ROUND(MAX(AY25,AZ25)*3.412,0)) | BB25: 480 | BC25: 357.12 | BD25: 32 | BE25: 2 | BF25: Quad-core Cortex-A57 1.8GHz | BG25: 16384 | BH25: 4093 | BI25: 2K IPv4 / 2K IPv6 | BK25: Full L3 (static, RIP, OSPF, VRRP, PIM-SM/DM, PBR) | BL25: Yes (NSF) | BM25: 8 | BN25: Yes (exclusive with stacking) | BO25: PTPv2 1-step E2E Transparent Clock | BP25: No | BQ25: Yes | BR25: Yes | BS25: No | BT25: 50 | BU25: Front-to-back | BV25: No (Quiet / Cool modes) | BW25: 34.34 | BX25: 780202 | BY25: ProSAFE Limited Lifetime HW; Lifetime NBD replacement | BZ25: Cat 3 | CA25: Not listed | CK25: M4350 datasheet DS-M4350-30May25 (fw 14.0) [file: M3450_Datasheet_30May25.pdf] | CL25: 2026-09-27
A26: XSM4328CV | B26: M4350-24X4V | C26: M4350 | D26: NETGEAR AV and IT | E26: Switch | F26: Access / Edge | G26: AV UI; Engage; IT Web GUI; CLI; SNMP | H26: Active | L26: 1U rack | M26: 1 | N26: Full width | O26: 440 | P26: 400 | Q26: 43.2 | R26: 6.58 | S26: 0 | T26: 0 | U26: 24 | V26: 0 | W26: 0 | X26: 0 | Y26: 4 | Z26: 0 | AA26: 0 | AB26: 0 | AC26: 0 | AD26: 0 | AE26: 0 | AF26: =SUM(S26:AE26) | AH26: 100M only on ports 1-16. SFP28 25-28: 10G or 25G only | AI26: 24 | AJ26: 802.3at PoE+ | AK26: 30 | AL26: 576 | AM26: 720 | AN26: 576 | AO26: =IFERROR(AM26/AI26,"") | AS26: Internal fixed + modular slots | AT26: 880 | AU26: 1 | AV26: 1 | AW26: A: APS350W / APS600Wv2 / APS920W / APS2000W | AX26: 53.6 | AY26: 119.4 | AZ26: 907.8 | BA26: =IF(MAX(AY26,AZ26)=0,"",ROUND(MAX(AY26,AZ26)*3.412,0)) | BB26: 680 | BC26: 505.92 | BD26: 32 | BE26: 2 | BF26: Quad-core Cortex-A57 1.8GHz | BG26: 16384 | BH26: 4093 | BI26: 2K IPv4 / 2K IPv6 | BK26: Full L3 (static, RIP, OSPF, VRRP, PIM-SM/DM, PBR) | BL26: Yes (NSF) | BM26: 8 | BN26: Yes (exclusive with stacking) | BO26: PTPv2 1-step E2E Transparent Clock | BP26: No | BQ26: Yes | BR26: Yes | BS26: No | BT26: 45 | BU26: Front-to-back | BV26: No (Quiet / Cool modes) | BW26: 34.7 | BX26: 486832 | BY26: ProSAFE Limited Lifetime HW; Lifetime NBD replacement | BZ26: Cat 3 | CA26: Yes (-TAANES) | CK26: M4350 datasheet DS-M4350-30May25 (fw 14.0) [file: M3450_Datasheet_30May25.pdf] | CL26: 2026-09-27
A27: XSM4328FV | B27: M4350-24F4V | C27: M4350 | D27: NETGEAR AV and IT | E27: Switch | F27: Aggregation / Core | G27: AV UI; Engage; IT Web GUI; CLI; SNMP | H27: Active | L27: 1U rack | M27: 1 | N27: Full width | O27: 440 | P27: 400 | Q27: 43.2 | R27: 6.25 | S27: 0 | T27: 0 | U27: 0 | V27: 0 | W27: 0 | X27: 24 | Y27: 4 | Z27: 0 | AA27: 0 | AB27: 0 | AC27: 0 | AD27: 0 | AE27: 0 | AF27: =SUM(S27:AE27) | AH27: 1G on SFP+ 1-16 only. SFP28 25-28: 10G or 25G only | AI27: 0 | AJ27: None | AO27: =IFERROR(AM27/AI27,"") | AS27: Internal fixed + modular slots | AT27: 240 | AU27: 1 | AV27: 1 | AW27: A: APS350W / APS600Wv2 / APS920W / APS2000W | AX27: 45.2 | AY27: 119.3 | BA27: =IF(MAX(AY27,AZ27)=0,"",ROUND(MAX(AY27,AZ27)*3.412,0)) | BB27: 680 | BC27: 505.92 | BD27: 32 | BE27: 2 | BF27: Quad-core Cortex-A57 1.8GHz | BG27: 16384 | BH27: 4093 | BI27: 2K IPv4 / 2K IPv6 | BK27: Full L3 (static, RIP, OSPF, VRRP, PIM-SM/DM, PBR) | BL27: Yes (NSF) | BM27: 8 | BN27: Yes (exclusive with stacking) | BO27: PTPv2 1-step E2E Transparent Clock | BP27: No | BQ27: Yes | BR27: Yes | BS27: No | BT27: 50 | BU27: Front-to-back | BV27: No (Quiet / Cool modes) | BW27: 34.2 | BX27: 778741 | BY27: ProSAFE Limited Lifetime HW; Lifetime NBD replacement | BZ27: Cat 3 | CA27: Not listed | CK27: M4350 datasheet DS-M4350-30May25 (fw 14.0) [file: M3450_Datasheet_30May25.pdf] | CL27: 2026-09-27 | CM27: Modular slot = RPS only (no PoE)
A28: XSM4340CV | B28: M4350-36X4V | C28: M4350 | D28: NETGEAR AV and IT | E28: Switch | F28: Access / Edge | G28: AV UI; Engage; IT Web GUI; CLI; SNMP | H28: Active | L28: 1U rack | M28: 1 | N28: Full width | O28: 440 | P28: 400 | Q28: 43.2 | R28: 7.33 | S28: 0 | T28: 0 | U28: 36 | V28: 0 | W28: 0 | X28: 0 | Y28: 4 | Z28: 0 | AA28: 0 | AB28: 0 | AC28: 0 | AD28: 0 | AE28: 0 | AF28: =SUM(S28:AE28) | AH28: 100M only on ports 1-28 | AI28: 36 | AJ28: 802.3bt Ultra90 PoE++ | AK28: 90 | AL28: 280 | AM28: 1760 | AN28: 280 | AO28: =IFERROR(AM28/AI28,"") | AS28: Internal fixed + modular slots | AT28: 750 | AU28: 1 | AV28: 1 | AW28: B: APS600Wv3 / APS1200Wv2 / APS2000Wv2 | AX28: 59.3 | AY28: 148 | AZ28: 2071.4 | BA28: =IF(MAX(AY28,AZ28)=0,"",ROUND(MAX(AY28,AZ28)*3.412,0)) | BB28: 920 | BC28: 684.48 | BD28: 64 | BE28: 4 | BF28: Quad-core Cortex-A57 1.8GHz | BG28: 16384 | BH28: 4093 | BI28: 2K IPv4 / 2K IPv6 | BK28: Full L3 (static, RIP, OSPF, VRRP, PIM-SM/DM, PBR) | BL28: Yes (NSF) | BM28: 8 | BN28: Yes (exclusive with stacking) | BO28: PTPv2 1-step E2E Transparent Clock | BP28: No | BQ28: Yes | BR28: Yes | BS28: No | BT28: 45 | BU28: Front-to-back | BV28: No (Quiet / Cool modes) | BW28: 32.1 | BX28: 292505 | BY28: ProSAFE Limited Lifetime HW; Lifetime NBD replacement | BZ28: Cat 4 | CA28: Not listed | CK28: M4350 datasheet DS-M4350-30May25 (fw 14.0) [file: M3450_Datasheet_30May25.pdf] | CL28: 2026-09-27
A29: XSM4340V | B29: M4350-24X8F8V | C29: M4350 | D29: NETGEAR AV and IT | E29: Switch | F29: Access / Edge | G29: AV UI; Engage; IT Web GUI; CLI; SNMP | H29: Active | L29: 1U rack | M29: 1 | N29: Full width | O29: 440 | P29: 400 | Q29: 43.2 | R29: 7.24 | S29: 0 | T29: 0 | U29: 24 | V29: 0 | W29: 0 | X29: 8 | Y29: 8 | Z29: 0 | AA29: 0 | AB29: 0 | AC29: 0 | AD29: 0 | AE29: 0 | AF29: =SUM(S29:AE29) | AH29: 1G on SFP+ 25-28 only. SFP28 33-40: 10G or 25G per 4-port block | AI29: 24 | AJ29: 802.3bt Ultra90 PoE++ | AK29: 90 | AL29: 290 | AM29: 1770 | AN29: 290 | AO29: =IFERROR(AM29/AI29,"") | AS29: Internal fixed + modular slots | AT29: 750 | AU29: 1 | AV29: 1 | AW29: B: APS600Wv3 / APS1200Wv2 / APS2000Wv2 | AX29: 53.4 | AY29: 151.8 | AZ29: 2057.3 | BA29: =IF(MAX(AY29,AZ29)=0,"",ROUND(MAX(AY29,AZ29)*3.412,0)) | BB29: 1040 | BC29: 773.76 | BD29: 64 | BE29: 4 | BF29: Quad-core Cortex-A57 1.8GHz | BG29: 16384 | BH29: 4093 | BI29: 2K IPv4 / 2K IPv6 | BK29: Full L3 (static, RIP, OSPF, VRRP, PIM-SM/DM, PBR) | BL29: Yes (NSF) | BM29: 8 | BN29: Yes (exclusive with stacking) | BO29: PTPv2 1-step E2E Transparent Clock | BP29: No | BQ29: Yes | BR29: Yes | BS29: No | BT29: 45 | BU29: Front-to-back | BV29: No (Quiet / Cool modes) | BW29: 32.6 | BX29: 386078 | BY29: ProSAFE Limited Lifetime HW; Lifetime NBD replacement | BZ29: Cat 4 | CA29: Yes (-TAANES) | CK29: M4350 datasheet DS-M4350-30May25 (fw 14.0) [file: M3450_Datasheet_30May25.pdf] | CL29: 2026-09-27
A30: XSM4340FV | B30: M4350-32F8V | C30: M4350 | D30: NETGEAR AV and IT | E30: Switch | F30: Aggregation / Core | G30: AV UI; Engage; IT Web GUI; CLI; SNMP | H30: Active | L30: 1U rack | M30: 1 | N30: Full width | O30: 440 | P30: 400 | Q30: 43.2 | R30: 6.95 | S30: 0 | T30: 0 | U30: 0 | V30: 0 | W30: 0 | X30: 32 | Y30: 8 | Z30: 0 | AA30: 0 | AB30: 0 | AC30: 0 | AD30: 0 | AE30: 0 | AF30: =SUM(S30:AE30) | AH30: 1G on SFP+ 1-28 only. SFP28 33-40: 10G or 25G per 4-port block | AI30: 0 | AJ30: None | AO30: =IFERROR(AM30/AI30,"") | AS30: Internal fixed + modular slots | AT30: 420 | AU30: 1 | AV30: 1 | AW30: B: APS600Wv3 / APS1200Wv2 / APS2000Wv2 | AX30: 42.6 | AY30: 156.4 | BA30: =IF(MAX(AY30,AZ30)=0,"",ROUND(MAX(AY30,AZ30)*3.412,0)) | BB30: 1040 | BC30: 773.76 | BD30: 64 | BE30: 4 | BF30: Quad-core Cortex-A57 1.8GHz | BG30: 16384 | BH30: 4093 | BI30: 2K IPv4 / 2K IPv6 | BK30: Full L3 (static, RIP, OSPF, VRRP, PIM-SM/DM, PBR) | BL30: Yes (NSF) | BM30: 8 | BN30: Yes (exclusive with stacking) | BO30: PTPv2 1-step E2E Transparent Clock | BP30: No | BQ30: Yes | BR30: Yes | BS30: No | BT30: 50 | BU30: Front-to-back | BV30: No (Quiet / Cool modes) | BW30: 32.7 | BX30: 582420 | BY30: ProSAFE Limited Lifetime HW; Lifetime NBD replacement | BZ30: Cat 4 | CA30: Yes (-TAANES) | CK30: M4350 datasheet DS-M4350-30May25 (fw 14.0) [file: M3450_Datasheet_30May25.pdf] | CL30: 2026-09-27 | CM30: Modular slot = RPS only (no PoE)
A31: VSM4320C | B31: M4350-16V4C | C31: M4350 | D31: NETGEAR AV and IT | E31: Switch | F31: Aggregation / Core | G31: AV UI; Engage; IT Web GUI; CLI; SNMP | H31: Active | L31: 1U rack | M31: 1 | N31: Full width | O31: 440 | P31: 400 | Q31: 43.2 | R31: 7.15 | S31: 0 | T31: 0 | U31: 0 | V31: 0 | W31: 0 | X31: 0 | Y31: 16 | Z31: 4 | AA31: 0 | AB31: 0 | AC31: 0 | AD31: 0 | AE31: 0 | AF31: =SUM(S31:AE31) | AH31: SFP28: 10G or 25G per 4-port block, no stacking on SFP28. QSFP28: 40/100G or 4x25G breakout | AI31: 0 | AJ31: None | AO31: =IFERROR(AM31/AI31,"") | AS31: Internal fixed + modular slots | AT31: 420 | AU31: 1 | AV31: 1 | AW31: B: APS600Wv3 / APS1200Wv2 / APS2000Wv2 | AX31: 60.4 | AY31: 143.4 | BA31: =IF(MAX(AY31,AZ31)=0,"",ROUND(MAX(AY31,AZ31)*3.412,0)) | BB31: 1600 | BC31: 1190.4 | BD31: 256 | BE31: 4 | BF31: Quad-core Cortex-A57 1.8GHz | BG31: 16384 | BH31: 4093 | BI31: 2K IPv4 / 2K IPv6 | BK31: Full L3 (static, RIP, OSPF, VRRP, PIM-SM/DM, PBR) | BL31: Yes (NSF) | BM31: 8 | BN31: Yes (exclusive with stacking) | BO31: PTPv2 TC + Boundary/Grandmaster (SMPTE 2059-2, AES67, AES-R16) | BP31: Yes | BQ31: Yes | BR31: Yes | BS31: No | BT31: 50 | BU31: Front-to-back | BV31: No (Quiet / Cool modes) | BW31: 36.4 | BX31: 518782 | BY31: ProSAFE Limited Lifetime HW; Lifetime NBD replacement | BZ31: Cat 4 | CA31: Yes (-TAANES) | CK31: M4350 datasheet DS-M4350-30May25 (fw 14.0) [file: M3450_Datasheet_30May25.pdf] | CL31: 2026-09-27 | CM31: Modular slot = RPS only (no PoE)
A32: XSM4344C | B32: M4350-40X4C | C32: M4350 | D32: NETGEAR AV and IT | E32: Switch | F32: Access / Edge | G32: AV UI; Engage; IT Web GUI; CLI; SNMP | H32: Active | L32: 1U rack | M32: 1 | N32: Full width | O32: 440 | P32: 400 | Q32: 43.2 | R32: 7.76 | S32: 0 | T32: 0 | U32: 40 | V32: 0 | W32: 0 | X32: 0 | Y32: 0 | Z32: 4 | AA32: 0 | AB32: 0 | AC32: 0 | AD32: 0 | AE32: 0 | AF32: =SUM(S32:AE32) | AH32: 10G RJ45: no 100M on any port. QSFP28: 40/100G or 4x25G breakout | AI32: 40 | AJ32: 802.3bt Ultra90 PoE++ | AK32: 90 | AL32: 196 | AM32: 1676 | AN32: 196 | AO32: =IFERROR(AM32/AI32,"") | AS32: Internal fixed + modular slots | AT32: 750 | AU32: 1 | AV32: 1 | AW32: B: APS600Wv3 / APS1200Wv2 / APS2000Wv2 | AX32: 98.8 | AY32: 200.4 | AZ32: 2018.3 | BA32: =IF(MAX(AY32,AZ32)=0,"",ROUND(MAX(AY32,AZ32)*3.412,0)) | BB32: 1600 | BC32: 1190.4 | BD32: 256 | BE32: 4 | BF32: Quad-core Cortex-A57 1.8GHz | BG32: 16384 | BH32: 4093 | BI32: 2K IPv4 / 2K IPv6 | BK32: Full L3 (static, RIP, OSPF, VRRP, PIM-SM/DM, PBR) | BL32: Yes (NSF) | BM32: 8 | BN32: Yes (exclusive with stacking) | BO32: PTPv2 TC + Boundary/Grandmaster (SMPTE 2059-2, AES67, AES-R16) | BP32: Yes | BQ32: Yes | BR32: Yes | BS32: No | BT32: 45 | BU32: Front-to-back | BV32: No (Quiet / Cool modes) | BW32: 34.1 | BX32: 229375 | BY32: ProSAFE Limited Lifetime HW; Lifetime NBD replacement | BZ32: Cat 4 | CA32: Yes (-TAANES) | CK32: M4350 datasheet DS-M4350-30May25 (fw 14.0) [file: M3450_Datasheet_30May25.pdf] | CL32: 2026-09-27
A33: XSM4344FC | B33: M4350-40F4C | C33: M4350 | D33: NETGEAR AV and IT | E33: Switch | F33: Aggregation / Core | G33: AV UI; Engage; IT Web GUI; CLI; SNMP | H33: Active | L33: 1U rack | M33: 1 | N33: Full width | O33: 440 | P33: 400 | Q33: 43.2 | R33: 7.38 | S33: 0 | T33: 0 | U33: 0 | V33: 0 | W33: 0 | X33: 40 | Y33: 0 | Z33: 4 | AA33: 0 | AB33: 0 | AC33: 0 | AD33: 0 | AE33: 0 | AF33: =SUM(S33:AE33) | AH33: SFP+ 1-40: 1G or 10G only. QSFP28: 40/100G or 4x25G breakout | AI33: 0 | AJ33: None | AO33: =IFERROR(AM33/AI33,"") | AS33: Internal fixed + modular slots | AT33: 420 | AU33: 1 | AV33: 1 | AW33: B: APS600Wv3 / APS1200Wv2 / APS2000Wv2 | AX33: 65 | AY33: 213.6 | BA33: =IF(MAX(AY33,AZ33)=0,"",ROUND(MAX(AY33,AZ33)*3.412,0)) | BB33: 1600 | BC33: 1190.4 | BD33: 256 | BE33: 4 | BF33: Quad-core Cortex-A57 1.8GHz | BG33: 16384 | BH33: 4093 | BI33: 2K IPv4 / 2K IPv6 | BK33: Full L3 (static, RIP, OSPF, VRRP, PIM-SM/DM, PBR) | BL33: Yes (NSF) | BM33: 8 | BN33: Yes (exclusive with stacking) | BO33: PTPv2 TC + Boundary/Grandmaster (SMPTE 2059-2, AES67, AES-R16) | BP33: Yes | BQ33: Yes | BR33: Yes | BS33: No | BT33: 50 | BU33: Front-to-back | BV33: No (Quiet / Cool modes) | BW33: 34 | BX33: 380163 | BY33: ProSAFE Limited Lifetime HW; Lifetime NBD replacement | BZ33: Cat 4 | CA33: Yes (-TAANES) | CK33: M4350 datasheet DS-M4350-30May25 (fw 14.0) [file: M3450_Datasheet_30May25.pdf] | CL33: 2026-09-27 | CM33: Modular slot = RPS only (no PoE)
A34: PR460X | B34: PR460X Pro Router | C34: PR460X | D34: NETGEAR AV / Insight Pro | E34: Router | F34: Gateway / Router | G34: Insight (cloud) OR Engage - not both; Domotz | H34: Active | L34: 1U rack (reversible ears) | M34: 1 | N34: Full width | O34: 440 | P34: 100 | Q34: 43.2 | R34: 1.513 | S34: 0 | T34: 4 | U34: 1 | V34: 0 | W34: 0 | X34: 1 | Y34: 0 | Z34: 0 | AA34: 0 | AB34: 0 | AC34: 0 | AD34: 0 | AE34: 0 | AF34: =SUM(S34:AE34) | AH34: 1x 10G multi-gig (WAN/LAN configurable), 1x 2.5G WAN, 3x 2.5G LAN, 1x 10G SFP+ LAN | AI34: 0 | AJ34: None | AO34: =IFERROR(AM34/AI34,"") | AS34: Internal AC 100-240V, 1.3A | AU34: 1 | AV34: 0 | AW34: None (fixed) | BA34: =IF(MAX(AY34,AZ34)=0,"",ROUND(MAX(AY34,AZ34)*3.412,0)) | BH34: 32 | BK34: NAT router; static, RIPv1/v2; 32 DHCP servers | BL34: No | BN34: No | BP34: No | BR34: Yes (Engage v2) | BS34: Yes | BT34: 40 | BY34: Enterprise Limited Lifetime HW | BZ34: Sprint / Overdrive (SKUs not in datasheet) | CA34: Not listed | CB34: 4-yr Insight subscription | CC34: 2 (dual WAN failover / load balancing) | CD34: 2.4 Gbps (2.5G WAN) / 9.4 Gbps (10G WAN) | CE34: IPSec S2S 30 tunnels; IPSec/OpenVPN/WireGuard client 100 each; S2S 4.42/8.92 Gbps, client 500 Mbps | CF34: 2000 | CK34: PR460X datasheet NG_DS_AV_PR460X-042926 | CL34: 2026-09-27 | CM34: Concurrent connections: 60,000 (spec table) vs 250,000 (features table) - verify. Optional Exium security license (SEC-PR460X-xx), Insight path only.
A35: WBE718 | B35: WBE718 WiFi 7 AP | C35: WBE7xx | D35: Insight Pro WiFi | E35: Access Point | F35: Wireless AP (indoor) | G35: Insight (cloud / app) | H35: Active | L35: Wall / ceiling | N35: Ceiling/Wall | O35: 157 | P35: 157 | Q35: 40 | R35: 0.69 | S35: 0 | T35: 1 | U35: 0 | V35: 0 | W35: 0 | X35: 0 | Y35: 0 | Z35: 0 | AA35: 0 | AB35: 0 | AC35: 0 | AD35: 0 | AE35: 0 | AF35: =SUM(S35:AE35) | AH35: 1x 2.5G PoE PD uplink | AI35: 0 | AJ35: PD | AO35: =IFERROR(AM35/AI35,"") | AP35: 25 | AQ35: 802.3at (af = reduced: -50% 2.4G, -25% 5G, no 6G) | AR35: 2.5G | AS35: PoE or 12V/2.5A adapter (not incl.) | AV35: 0 | AW35: None | BA35: =IF(MAX(AY35,AZ35)=0,"",ROUND(MAX(AY35,AZ35)*3.412,0)) | BR35: Yes (select APs, Engage v2) | BS35: Yes | BT35: 40 | BY35: Enterprise Limited Lifetime HW | BZ35: SPR-/DRV-WBE718 | CA35: Not listed | CB35: 4-yr Insight subscription | CG35: WiFi 7 (802.11be) tri-band | CH35: 2x2 per band (6 streams) | CI35: 9.4 | CJ35: 8 | CK35: WBE718 datasheet DS-WBE718_02Apr26 | CL35: 2026-09-27 | CM35: Weight shown as 0.69 kg (2.09 lb) - lb value inconsistent, verify. Engage support per PR460X datasheet ('select APs') - confirm model list.
A36: WBE758 | B36: WBE758 WiFi 7 AP | C36: WBE7xx | D36: Insight Pro WiFi | E36: Access Point | F36: Wireless AP (indoor) | G36: Insight (cloud / app) | H36: Active | L36: Wall / ceiling | N36: Ceiling/Wall | O36: 172 | P36: 172 | Q36: 44 | R36: 0.95 | S36: 0 | T36: 0 | U36: 1 | V36: 0 | W36: 0 | X36: 0 | Y36: 0 | Z36: 0 | AA36: 0 | AB36: 0 | AC36: 0 | AD36: 0 | AE36: 0 | AF36: =SUM(S36:AE36) | AH36: 1x 10G PoE++ PD uplink | AI36: 0 | AJ36: PD | AO36: =IFERROR(AM36/AI36,"") | AP36: 39 | AQ36: 802.3bt (at = reduced: -50% 2.4G, -25% 5G/6G; af not supported) | AR36: 10G | AS36: PoE or 12V/3.5A adapter (not incl.) | AV36: 0 | AW36: None | BA36: =IF(MAX(AY36,AZ36)=0,"",ROUND(MAX(AY36,AZ36)*3.412,0)) | BR36: Yes (select APs, Engage v2) | BS36: Yes | BT36: 40 | BY36: Enterprise Limited Lifetime HW | BZ36: SPR-/DRV-WBE758 | CA36: Not listed | CB36: 4-yr Insight subscription | CG36: WiFi 7 (802.11be) tri-band | CH36: 4x4 per band (12 streams) | CI36: 18.4 | CJ36: 8 | CK36: WBE758 datasheet D-WBE758_29Jan24 | CL36: 2026-09-27 | CM36: Datasheet intro says 7.8 Gbps, spec table 18.4 Gbps - verify. 2.4GHz listed as 802.11b/g/n/ax (no be).

Sheet SKUs
A1: Orderable SKUs by Region
A2: Product_ID links to Products. Add every orderable variant here (regional, TAA, bundles).
A4: Product_ID | B4: Model_Name | C4: Orderable_SKU | D4: Region | E4: Power_Cord | F4: TAA_Compliant | G4: Notes
A5: GSM4210PD | B5: M4250-9G1F-PoE+ | C5: GSM4210PD-100NAS | D5: Americas | E5: Region cord | F5: No
A6: GSM4210PD | B6: M4250-9G1F-PoE+ | C6: GSM4210PD-100EUS | D6: Europe | E6: Region cord | F6: No
A7: GSM4210PD | B7: M4250-9G1F-PoE+ | C7: GSM4210PD-100INS | D7: India | E7: Region cord | F7: No
A8: GSM4210PD | B8: M4250-9G1F-PoE+ | C8: GSM4210PD-100JPS | D8: Japan | E8: Region cord | F8: No
A9: GSM4210PD | B9: M4250-9G1F-PoE+ | C9: GSM4210PD-100KOS | D9: South Korea | E9: Region cord | F9: No
A10: GSM4210PD | B10: M4250-9G1F-PoE+ | C10: GSM4210PD-100TWS | D10: Taiwan | E10: Region cord | F10: No
A11: GSM4210PD | B11: M4250-9G1F-PoE+ | C11: GSM4210PD-100UKS | D11: Hong Kong | E11: Region cord | F11: No
A12: GSM4210PD | B12: M4250-9G1F-PoE+ | C12: GSM4210PD-100AUS | D12: Australia | E12: Region cord | F12: No
A13: GSM4210PD | B13: M4250-9G1F-PoE+ | C13: GSM4210PD-100PRS | D13: China | E13: Region cord | F13: No
A14: GSM4210PD | B14: M4250-9G1F-PoE+ | C14: GSM4210PD-100PES | D14: Other APAC | E14: Region cord | F14: No
A15: GSM4210PX | B15: M4250-8G2XF-PoE+ | C15: GSM4210PX-100NAS | D15: Americas | E15: Region cord | F15: No
A16: GSM4210PX | B16: M4250-8G2XF-PoE+ | C16: GSM4210PX-100EUS | D16: Europe | E16: Region cord | F16: No
... A141: WBE758 | B141: WBE758 WiFi 7 AP | C141: WBE758-111APS | D141: Asia Pacific | E141: Adapter not incl. | F141: No

Sheet Accessories
A1: Accessories, PSUs, Optics, Cables, Licenses & Support
A2: Base_Model groups variants (e.g. cord options). Compatibility sheet maps Base_Model to products.
A4: Orderable_SKU | B4: Base_Model | C4: Category | D4: Description | E4: Form_Factor | F4: Speed_Gbps | G4: Media | H4: Connector | I4: Reach_m | J4: Fiber_Notes | K4: Output_W_110VAC | L4: Output_W_220VAC | M4: Power_Cord | N4: Term_Months | O4: Warranty | P4: Source | Q4: Notes
A5: AGM731F | B5: AGM731F | C5: Optic | D5: 1000BASE-SX SFP, multimode | E5: SFP | F5: 1 | G5: MMF | H5: LC duplex | I5: 550 | J5: OM1/OM2 275m; OM3 550m; OM4 1,000m | O5: 5 yr | P5: M4250 + M4350 datasheets
A6: AGM732F | B6: AGM732F | C6: Optic | D6: 1000BASE-LX SFP, single mode | E6: SFP | F6: 1 | G6: SMF | H6: LC duplex | I6: 10000 | J6: OS 9/125um | O6: 5 yr | P6: M4250 + M4350 datasheets
A7: AGM734-10000S | B7: AGM734 | C7: Optic | D7: 1000BASE-T RJ45 SFP (1000 Mbps full duplex only) | E7: SFP | F7: 1 | G7: Copper | H7: RJ45 | I7: 100 | J7: Cat5 or better | O7: 5 yr | P7: M4250 + M4350 datasheets | Q7: M4250-16XF: ports 1-12 only
A8: AXM761-10000S | B8: AXM761 | C8: Optic | D8: 10GBASE-SR SFP+, multimode | E8: SFP+ | F8: 10 | G8: MMF | H8: LC duplex | I8: 300 | J8: OM3/OM4 300m; OM1/OM2 33m | O8: 5 yr | P8: M4250 + M4350 datasheets
A9: AXM761P10-10000S | B9: AXM761 | C9: Optic | D9: 10GBASE-SR SFP+, pack of 10 | E9: SFP+ | F9: 10 | G9: MMF | H9: LC duplex | I9: 300 | J9: OM3/OM4 300m; OM1/OM2 33m | O9: 5 yr | P9: M4250 + M4350 datasheets | Q9: Qty 10 per SKU
A10: AXM762-10000S | B10: AXM762 | C10: Optic | D10: 10GBASE-LR SFP+, single mode | E10: SFP+ | F10: 10 | G10: SMF | H10: LC duplex | I10: 10000 | J10: OS 9/125um | O10: 5 yr | P10: M4250 + M4350 datasheets
A11: AXM762P10-10000S | B11: AXM762 | C11: Optic | D11: 10GBASE-LR SFP+, pack of 10 | E11: SFP+ | F11: 10 | G11: SMF | H11: LC duplex | I11: 10000 | J11: OS 9/125um | O11: 5 yr | P11: M4250 + M4350 datasheets | Q11: Qty 10 per SKU
A12: AXM763-10000S | B12: AXM763 | C12: Optic | D12: 10GBASE-LRM SFP+, multimode (802.3aq) | E12: SFP+ | F12: 10 | G12: MMF | H12: LC duplex | I12: 165 | J12: OM3/OM4 165m; OM1/OM2 100m | O12: 5 yr | P12: M4250 + M4350 datasheets
A13: AXM764-10000S | B13: AXM764 | C13: Optic | D13: 10GBASE-LR LITE SFP+, single mode | E13: SFP+ | F13: 10 | G13: SMF | H13: LC duplex | I13: 2000 | J13: OS 9/125um | O13: 5 yr | P13: M4250 + M4350 datasheets
A14: AXM765-20000S | B14: AXM765 | C14: Optic | D14: 10GBASE-T RJ45 SFP+ | E14: SFP+ | F14: 10 | G14: Copper | H14: RJ45 | I14: 80 | J14: Cat6a or better | O14: 5 yr | P14: M4250 + M4350 datasheets
A15: AXC761-10000S | B15: AXC761 | C15: DAC | D15: 10G SFP+ DAC 1m, passive copper | E15: SFP+ | F15: 10 | G15: DAC passive | H15: SFP+ | I15: 1 | O15: 5 yr | P15: M4250 + M4350 datasheets
A16: AXC763-10000S | B16: AXC763 | C16: DAC | D16: 10G SFP+ DAC 3m, passive copper | E16: SFP+ | F16: 10 | G16: DAC passive | H16: SFP+ | I16: 3 | O16: 5 yr | P16: M4250 + M4350 datasheets
A17: AXC765-10000S | B17: AXC765 | C17: DAC | D17: 10G SFP+ DAC 5m, active copper | E17: SFP+ | F17: 10 | G17: DAC active | H17: SFP+ | I17: 5 | O17: 5 yr | P17: M4250 + M4350 datasheets
A18: AXC767-10000S | B18: AXC767 | C18: DAC | D18: 10G SFP+ DAC 7m, active copper | E18: SFP+ | F18: 10 | G18: DAC active | H18: SFP+ | I18: 7 | O18: 5 yr | P18: M4250 + M4350 datasheets
A19: AXC7610-10000S | B19: AXC7610 | C19: DAC | D19: 10G SFP+ DAC 10m, active copper | E19: SFP+ | F19: 10 | G19: DAC active | H19: SFP+ | I19: 10 | O19: 5 yr | P19: M4250 + M4350 datasheets
A20: AXC7615-10000S | B20: AXC7615 | C20: AOC | D20: 10G SFP+ 15m, fiber (AOC) | E20: SFP+ | F20: 10 | G20: AOC | H20: SFP+ | I20: 15 | O20: 5 yr | P20: M4250 + M4350 datasheets
A21: AXC7620-10000S | B21: AXC7620 | C21: AOC | D21: 10G SFP+ 20m, fiber (AOC) | E21: SFP+ | F21: 10 | G21: AOC | H21: SFP+ | I21: 20 | O21: 5 yr | P21: M4250 + M4350 datasheets
A22: APS254W-10000S | B22: APS254W | C22: Power Adapter | D22: 254W external power adapter (C14, no cord) | H22: C14 | K22: 254 | L22: 254 | M22: None | O22: 2 yr | P22: M4350 datasheet DS-M4350-30May25 (fw 14.0) [file: M3450_Datasheet_30May25.pdf] | Q22: For M4350-8M2V and M4250-8G2XF-PoE+
A23: APS350W-100NES | B23: APS350W | C23: PSU Module | D23: 350W modular PSU | H23: C14 | K23: 350 | L23: 350 | M23: NA/UK/EU cords | O23: 5 yr | P23: M4350 datasheet DS-M4350-30May25 (fw 14.0) [file: M3450_Datasheet_30May25.pdf] | Q23: PSU group A
A24: APS350W-100AJS | B24: APS350W | C24: PSU Module | D24: 350W modular PSU | H24: C14 | K24: 350 | L24: 350 | M24: JP/AU cords | O24: 5 yr | P24: M4350 datasheet DS-M4350-30May25 (fw 14.0) [file: M3450_Datasheet_30May25.pdf] | Q24: PSU group A
A25: APS350W-10000S | B25: APS350W | C25: PSU Module | D25: 350W modular PSU | H25: C14 | K25: 350 | L25: 350 | M25: No cord | O25: 5 yr | P25: M4350 datasheet DS-M4350-30May25 (fw 14.0) [file: M3450_Datasheet_30May25.pdf] | Q25: PSU group A
A26: APS600W-200NES | B26: APS600Wv2 | C26: PSU Module | D26: 600W modular PSU (v2) | H26: C14 | K26: 600 | L26: 600 | M26: NA/UK/EU cords | O26: 5 yr | P26: M4350 datasheet DS-M4350-30May25 (fw 14.0) [file: M3450_Datasheet_30May25.pdf] | Q26: PSU group A
A27: APS600W-200AJS | B27: APS600Wv2 | C27: PSU Module | D27: 600W modular PSU (v2) | H27: C14 | K27: 600 | L27: 600 | M27: JP/AU cords | O27: 5 yr | P27: M4350 datasheet DS-M4350-30May25 (fw 14.0) [file: M3450_Datasheet_30May25.pdf] | Q27: PSU group A
A28: APS600W-20000S | B28: APS600Wv2 | C28: PSU Module | D28: 600W modular PSU (v2) | H28: C14 | K28: 600 | L28: 600 | M28: No cord | O28: 5 yr | P28: M4350 datasheet DS-M4350-30May25 (fw 14.0) [file: M3450_Datasheet_30May25.pdf] | Q28: PSU group A
A29: APS920W-100NES | B29: APS920W | C29: PSU Module | D29: 920W modular PSU | H29: C14 | K29: 920 | L29: 920 | M29: NA/UK/EU cords | O29: 5 yr | P29: M4350 datasheet DS-M4350-30May25 (fw 14.0) [file: M3450_Datasheet_30May25.pdf] | Q29: PSU group A
A30: APS920W-100AJS | B30: APS920W | C30: PSU Module | D30: 920W modular PSU | H30: C14 | K30: 920 | L30: 920 | M30: JP/AU cords | O30: 5 yr | P30: M4350 datasheet DS-M4350-30May25 (fw 14.0) [file: M3450_Datasheet_30May25.pdf] | Q30: PSU group A
A31: APS920W-10000S | B31: APS920W | C31: PSU Module | D31: 920W modular PSU | H31: C14 | K31: 920 | L31: 920 | M31: No cord | O31: 5 yr | P31: M4350 datasheet DS-M4350-30May25 (fw 14.0) [file: M3450_Datasheet_30May25.pdf] | Q31: PSU group A
A32: APS2000W-100NES | B32: APS2000W | C32: PSU Module | D32: 2,000W modular PSU (1,000W @110V) | H32: C14 | K32: 1000 | L32: 2000 | M32: NA/UK/EU cords | O32: 5 yr | P32: M4350 datasheet DS-M4350-30May25 (fw 14.0) [file: M3450_Datasheet_30May25.pdf] | Q32: PSU group A
A33: APS2000W-100AJS | B33: APS2000W | C33: PSU Module | D33: 2,000W modular PSU (1,000W @110V) | H33: C14 | K33: 1000 | L33: 2000 | M33: JP/AU cords | O33: 5 yr | P33: M4350 datasheet DS-M4350-30May25 (fw 14.0) [file: M3450_Datasheet_30May25.pdf] | Q33: PSU group A
... A43: APS2000W-20000S | B43: APS2000Wv2 | C43: PSU Module | D43: 2,000W modular PSU v2 (1,000W @110V) | H43: C14 | K43: 1000 | L43: 2000 | M43: No cord | O43: 5 yr | P43: M4350 datasheet DS-M4350-30May25 (fw 14.0) [file: M3450_Datasheet_30May25.pdf] | Q43: PSU group B
A44: PST4310-10000S | B44: PST4310 | C44: PSU Tray | D44: Half-width PSU tray for M4350-8M2V (holds 2x APS254W) | P44: M4350 datasheet DS-M4350-30May25 (fw 14.0) [file: M3450_Datasheet_30May25.pdf]
A45: SEC-PR460X-01 | B45: SEC-PR460X | C45: License | D45: Exium security license - monthly | N45: 1 | P45: PR460X datasheet NG_DS_AV_PR460X-042926 | Q45: SKUs marked WIP in datasheet
A46: SEC-PR460X-12 | B46: SEC-PR460X | C46: License | D46: Exium security license - 1 year | N46: 12 | P46: PR460X datasheet NG_DS_AV_PR460X-042926 | Q46: SKUs marked WIP in datasheet
A47: SEC-PR460X-36 | B47: SEC-PR460X | C47: License | D47: Exium security license - 3 year | N47: 36 | P47: PR460X datasheet NG_DS_AV_PR460X-042926 | Q47: SKUs marked WIP in datasheet
A48: SEC-PR460X-60 | B48: SEC-PR460X | C48: License | D48: Exium security license - 5 year | N48: 60 | P48: PR460X datasheet NG_DS_AV_PR460X-042926 | Q48: SKUs marked WIP in datasheet
A49: PSB0304-10000S | B49: PSB0304 | C49: Service | D49: Remote installation setup & config (2-hr appointment) | P49: M4250 datasheet DS-M4250-9Nov23 (fw 13.0.4) | Q49: All M4250 models
A50: PMB0312-10000S | B50: OnCall Cat 2 | C50: Support | D50: OnCall 24x7 1-year Cat 2 | N50: 12 | P50: M4250 datasheet DS-M4250-9Nov23 (fw 13.0.4)
...

Sheet Compatibility
A1: Compatibility Map
A2: Scope_Type = Product (one Product_ID) or Family (applies to every product in that Family). Accessory_Base links to Accessories.Base_Model.
A4: Scope_Type | B4: Scope_Value | C4: Port_or_Slot | D4: Accessory_Base | E4: Relationship | F4: Max_Qty | G4: Constraint_Notes
A5: Family | B5: M4250 | C5: SFP (1G) | D5: AGM731F | E5: Optional optic | G5: 1G module
A6: Family | B6: M4250 | C6: SFP (1G) | D6: AGM732F | E6: Optional optic | G6: 1G module
A7: Family | B7: M4250 | C7: SFP (1G) | D7: AGM734 | E7: Optional optic | G7: 1G module
A8: Family | B8: M4250 | C8: SFP+ | D8: AGM731F | E8: Optional optic | G8: M4250-16XF: 1G modules on ports 1-12 only
A9: Family | B9: M4250 | C9: SFP+ | D9: AGM732F | E9: Optional optic | G9: M4250-16XF: 1G modules on ports 1-12 only
A10: Family | B10: M4250 | C10: SFP+ | D10: AGM734 | E10: Optional optic | G10: M4250-16XF: 1G modules on ports 1-12 only
